<?xml version="1.0"?>
<robot name="bumperbot" xmlns:xacro="http://ros.org/wiki/xacro">
    
    <!-- Include other xacro files -->
    <xacro:include filename="$(find bumperbot_description)/urdf/bumperbot_gazebo.xacro"/>

    <!-- Base footprint link -->
    <link name="base_footprint"/>

    <!-- Base link -->
    <link name="base_link">
        <inertial>
            <origin xyz="0 0 0.04" rpy="0.0 0.25 0.3" />
            <mass value="0.82573504"/>
            <inertia ixx="0.022124416" ixy="-0.000122941" ixz="0.00034938785"
                     iyy="0.021193702" iyz="-0.000050120904"
                     izz="0.020064271" />
        </inertial>
        <visual>
            <origin rpy="0 0 0" xyz="0 0 0"/>
            <geometry>
                <mesh filename="package://bumperbot_description/meshes/base_link.STL"/>
            </geometry>
        </visual>
        <collision>
            <origin rpy="0 0 0" xyz="0 0 0"/>
            <geometry>
                <mesh filename="package://bumperbot_description/meshes/base_link.STL"/>
            </geometry>
        </collision>
    </link>

    <!-- Base joint -->
    <joint name="base_joint" type="fixed">
        <parent link="base_footprint"/>
        <child link="base_link"/>
        <origin rpy="0 0 0" xyz="0 0 0.033"/>
    </joint>

    <!-- Right wheel link -->
    <link name="wheel_right_link">
        <inertial>
            <origin xyz="0 -0.014 0" rpy="0 0 0" />
            <mass value="0.0530086" />
            <inertia ixx="1.881763e-05" ixy="-4.8444933e-10" ixz="1.8816371e-08"
                     iyy="3.1151074e-05" iyz="-6.9356066e-11"
                     izz="1.880197e-05" />
        </inertial>
        <visual>
            <origin rpy="1.57 0 0" xyz="0 0 0"/>
            <geometry>
                <mesh filename="package://bumperbot_description/meshes/wheel_right_link.STL"/>
            </geometry>
        </visual>
        <collision>
            <origin rpy="0 -0.015 0" xyz="0 0 0"/>
            <geometry>
                <sphere radius="0.033"/>
            </geometry>
        </collision>
    </link>

    <!-- Right wheel joint -->
    <joint name="wheel_right_joint" type="continuous">
        <parent link="base_link"/>
        <child link="wheel_right_link"/>
        <axis xyz="0 1 0"/>
        <origin rpy="0 0 0" xyz="0 -0.07 0"/>
    </joint>

    <!-- Left wheel link -->
    <link name="wheel_left_link">
        <inertial>
            <origin xyz="0 0.014 0" rpy="0 0 0" />
            <mass value="0.0530086" />
            <inertia ixx="1.8792911e-05" ixy="3.3125639e-10" ixz="-1.140820e-08"
                     iyy="3.1151074e-05" iyz="-3.6049925e-10"
                     izz="1.8826689e-05" />
        </inertial>
        <visual>
            <geometry>
                <mesh filename="package://bumperbot_description/meshes/wheel_left_link.STL"/>
            </geometry>
            <origin rpy="-1.57 0 0" xyz="0 0 0"/>
        </visual>
        <collision>
            <origin rpy="0 0.015 0" xyz="0 0 0"/>
            <geometry>
                <sphere radius="0.033"/>
            </geometry>
        </collision>
    </link>

    <!-- Left wheel joint -->
    <joint name="wheel_left_joint" type="continuous">
        <parent link="base_link"/>
        <child link="wheel_left_link"/>
        <axis xyz="0 1 0"/>
        <origin rpy="0 0 0" xyz="0 0.07 0"/>
    </joint>

    <!-- Front caster link -->
    <link name="caster_front_link">
        <inertial>
            <origin xyz="3.8996813e-07 2.4007300e-07 0.00219173397061506" rpy="0 0 0" />
            <mass value="1.4437927e-06" />
            <inertia ixx="7.2307528e-11" ixy="-6.1095688e-16" ixz="2.2284969e-15"
                     iyy="3.8713793e-11" iyz="2.9390986e-15"
                     izz="1.0096749e-10" />
        </inertial>
        <visual>
            <geometry>
                <mesh filename="package://bumperbot_description/meshes/caster_front_link.STL"/>
            </geometry>
            <origin rpy="0 0 0" xyz="0 0 0"/>
        </visual>
        <collision>
            <origin xyz="0 0 0" rpy="0 0 0"/>
            <geometry>
                <sphere radius="0.005"/>
            </geometry>
        </collision>
    </link>

    <!-- Front caster joint -->
    <joint name="caster_front_joint" type="fixed">
        <parent link="base_link"/>
        <child link="caster_front_link"/>
        <origin rpy="0 0 0" xyz="0.0475 0 -0.0275"/>
    </joint>

    <!-- Rear caster link -->
    <link name="caster_rear_link">
        <inertial>
            <origin xyz="3.8996813e-07 2.4007300e-07 0.00219173397061509" rpy="0 0 0" />
            <mass value="1.4437927e-06" />
            <inertia ixx="7.2307528e-11" ixy="-6.1095687e-16" ixz="2.2284969e-15"
                     iyy="3.8713793e-11" iyz="2.9390986e-15"
                     izz="1.0096749e-10" />
        </inertial>
        <visual>
            <geometry>
                <mesh filename="package://bumperbot_description/meshes/caster_rear_link.STL"/>
            </geometry>
            <origin rpy="0 0 0" xyz="0 0 0"/>
        </visual>
        <collision>
            <origin xyz="0 0 0" rpy="0 0 0"/>
            <geometry>
                <sphere radius="0.005"/>
            </geometry>
        </collision>
    </link>

    <!-- Rear caster joint -->
    <joint name="caster_rear_joint" type="fixed">
        <parent link="base_link"/>
        <child link="caster_rear_link"/>
        <origin rpy="0 0 0" xyz="-0.0475 0 -0.0275"/>
    </joint>

    <!-- Example for an additional link (commented out)
    <link name="can_link">
        <visual>
            <geometry>
                <mesh filename="package://bumperbot_description/meshes/can.STL"/>
            </geometry>
            <origin rpy="0 0 0" xyz="0 0 0"/>
        </visual>
    </link>

    <joint name="can_joint" type="fixed">
        <parent link="base_link"/>
        <child link="can_link"/>
        <origin rpy="1.57 0 0" xyz="-0.03 0.03 0.078"/>
    </joint>
    -->
</robot>
